Workbook

Sheet Cover
B2: CORPORATE VALUATION ANALYSIS
B4: Tesco PLC | LSE: TSCO | FTSE 100
B5: Discounted Cash Flow (DCF) & Trading Comparables Analysis
B7: Prepared by: | C7: Sanjana Nair
B8: Date: | C8: March 2026
B9: Currency: | C9: GBP (£ millions)
B10: Fiscal Year End: | C10: February / February
B11: Data Source: | C11: Tesco PLC Annual Reports FY2022–FY2025, Tesco Investor Relations & Stockanalysis.com
B13: WORKBOOK CONTENTS
B14: 1. Assumptions | C14: Key model drivers & inputs
B15: 2. Income Statement | C15: Historical & projected P&L (FY22–FY28E)
B16: 3. DCF Valuation | C16: WACC, UFCF, Terminal Value, Equity Bridge
B17: 4. Trading Comps | C17: EV/EBITDA & P/E peer benchmarking
B18: 5. Football Field | C18: Summary valuation output
B20: Disclaimer: This model is for educational and portfolio purposes only. All projections are based on publicly available information and analyst estimates. This does not constitute investment advice.

Sheet Assumptions
B1: MODEL ASSUMPTIONS — TESCO PLC
B2: Blue = inputs you can change | Pale blue background = editable cell | All figures in £ millions unless stated
B4: A. REVENUE ASSUMPTIONS
B5: Assumption | C5: FY26E | D5: FY27E | E5: FY28E
B6: Revenue Growth Rate (%) | C6: 0.03 | D6: 0.028 | E6: 0.025
B7: UK & ROI Revenue Growth (%) | C7: 0.032 | D7: 0.03 | E7: 0.027
B8: Booker Revenue Growth (%) | C8: 0.025 | D8: 0.022 | E8: 0.02
B10: B. PROFITABILITY ASSUMPTIONS
B11: Assumption | C11: FY26E | D11: FY27E | E11: FY28E
B12: Gross Margin (%) | C12: 0.078 | D12: 0.079 | E12: 0.08
B13: EBITDA Margin (%) | C13: 0.057 | D13: 0.058 | E13: 0.059
B14: EBIT Margin (%) | C14: 0.038 | D14: 0.039 | E14: 0.04
B15: D&A as % of Revenue (%) | C15: 0.019 | D15: 0.019 | E15: 0.019
B16: Tax Rate (%) | C16: 0.25 | D16: 0.25 | E16: 0.25
B18: C. DCF / WACC ASSUMPTIONS
B19: Risk-Free Rate (10Y UK Gilt, %) | C19: 0.042
B20: Equity Risk Premium (%) | C20: 0.06
B21: Beta (Levered) | C21: 0.65
B22: Cost of Debt (pre-tax, %) | C22: 0.045
B23: Debt / (Debt + Equity) — Target Capital Structure (%) | C23: 0.35
B24: WACC (calculated below, %) | C24: =(C19+C21*C20)*(1-C23)+C22*(1-C16)*C23 -> 0.0644625
B25: Terminal Growth Rate (%) | C25: 0.02
B26: Projection Years | C26: 3
B27: WACC = Ke × (E/V) + Kd × (1–T) × (D/V) → Calculated: ~6.5%
B28: Ke = Rf + β × ERP = 4.2% + 0.65 × 6.0% = 8.1% | Kd (post-tax) = 4.5% × 75% = 3.4%
B30: D. WORKING CAPITAL & CAPEX ASSUMPTIONS
B31: Assumption | C31: FY26E | D31: FY27E | E31: FY28E
B32: Capex as % of Revenue (%) | C32: 0.02 | D32: 0.02 | E32: 0.019
B33: Change in Working Capital as % of Revenue (%) | C33: -0.003 | D33: -0.003 | E33: -0.002
B36: E. COLOUR CODING KEY
B37: Sample | C37: Hardcoded input — change to run scenarios
B38: Sample | C38: Formula / calculated value
B39: Sample | C39: Cross-sheet link
B40: Sample | C40: Subtotal / total row

Sheet Income Statement
B1: INCOME STATEMENT — TESCO PLC (£ millions)
B2: Historical: FY2022–FY2024 (actual) | FY2025E–FY2028E (projected)
B4: £ millions | C4: FY2022A | D4: FY2023A | E4: FY2024A | F4: FY2025A | G4: FY2026E | H4: FY2027E | I4: FY2028E
B5: REVENUE
B6: Group Revenue | C6: 64764 | D6: 65762 | E6: 68190 | F6: 69916 | G6: =F6*(1+Assumptions!C6) -> 72013.48 | H6: =G6*(1+Assumptions!D6) -> 74029.857 | I6: =H6*(1+Assumptions!E6) -> 75880.604
B7: Revenue Growth (%) | D7: =D6/C6-1 -> 0.015409796 | E7: =E6/D6-1 -> 0.036921018 | F7: =F6/E6-1 -> 0.025311629 | G7: =G6/F6-1 -> 0.03 | H7: =H6/G6-1 -> 0.028 | I7: =I6/H6-1 -> 0.025
B9: GROSS PROFIT
B10: Gross Profit | C10: 5012 | D10: 5171 | E10: 5359 | F10: 5504 | G10: =G6*Assumptions!C12 -> 5617.0514 | H10: =H6*Assumptions!D12 -> 5848.3587 | I10: =I6*Assumptions!E12 -> 6070.4483
B11: Gross Margin (%) | C11: =C10/C6 -> 0.077388673 | D11: =D10/D6 -> 0.078632037 | E11: =E10/E6 -> 0.078589236 | F11: =F10/F6 -> 0.078723039 | G11: =G10/G6 -> 0.078 | H11: =H10/H6 -> 0.079 | I11: =I10/I6 -> 0.08
B13: EBITDA
B14: EBITDA | C14: 2826 | D14: 3032 | E14: 3867 | F14: 4727 | G14: =G6*Assumptions!C13 -> 4104.7684 | H14: =H6*Assumptions!D13 -> 4293.7317 | I14: =I6*Assumptions!E13 -> 4476.9556
B15: EBITDA Margin (%) | C15: =C14/C6 -> 0.043635353 | D15: =D14/D6 -> 0.046105654 | E15: =E14/E6 -> 0.056709195 | F15: =F14/F6 -> 0.067609703 | G15: =G14/G6 -> 0.057 | H15: =H14/H6 -> 0.058 | I15: =I14/I6 -> 0.059
B17: EBIT & NET INCOME
B18: D&A | C18: 1270 | D18: 1290 | E18: 1310 | F18: 2016 | G18: =ROUND(G14*Assumptions!D15,0) -> 78 | H18: =ROUND(H14*Assumptions!E15,0) -> 82 | I18: =ROUND(I14*Assumptions!E15,0) -> 85
B19: EBIT | C19: 1556 | D19: 1742 | E19: 2557 | F19: =F14-F18 -> 2711 | G19: =G14-G18 -> 4026.7684 | H19: =H14-H18 -> 4211.7317 | I19: =I14-I18 -> 4391.9556
B20: Net Interest Expense | C20: 560 | D20: 590 | E20: 610 | F20: 496 | G20: =ROUND(G6*0.009,0) -> 648 | H20: =ROUND(H6*0.009,0) -> 666 | I20: =ROUND(I6*0.009,0) -> 683
B21: EBT | C21: 996 | D21: 1152 | E21: 1947 | F21: =F19-F20 -> 2215 | G21: =G19-G20 -> 3378.7684 | H21: =H19-H20 -> 3545.7317 | I21: =I19-I20 -> 3708.9556
B22: Taxation | C22: 225 | D22: 288 | E22: 467 | F22: 598 | G22: =ROUND(G21*Assumptions!C15,0) -> 64 | H22: =ROUND(H21*Assumptions!C15,0) -> 67 | I22: =ROUND(I21*Assumptions!C15,0) -> 70
B23: Net Income | C23: 771 | D23: 864 | E23: 1480 | F23: 1604 | G23: =G21-G22 -> 3314.7684 | H23: =H21-H22 -> 3478.7317 | I23: =I21-I22 -> 3638.9556
B25: KEY MARGINS & RATIOS
B26: EBIT Margin (%) | C26: =C19/C6 -> 0.024025693 | D26: =D19/D6 -> 0.026489462 | E26: =E19/E6 -> 0.037498167 | F26: =F19/F6 -> 0.038775102 | G26: =G19/G6 -> 0.055916869 | H26: =H19/H6 -> 0.056892339 | I26: =I19/I6 -> 0.057879819
B27: Net Profit Margin (%) | C27: =C23/C6 -> 0.011904762 | D27: =D23/D6 -> 0.013138287 | E27: =E23/E6 -> 0.021704062 | F27: =F23/F6 -> 0.022941816 | G27: =G23/G6 -> 0.046029832 | H27: =H23/H6 -> 0.046990928 | I27: =I23/I6 -> 0.047956335
B28: Effective Tax Rate (%) | C28: =C22/C21 -> 0.22590361 | D28: =D22/D21 -> 0.25 | E28: =E22/E21 -> 0.23985619 | F28: =F22/F21 -> 0.26997743 | G28: =G22/G21 -> 0.018941813 | H28: =H22/H21 -> 0.018895959 | I28: =I22/I21 -> 0.018873237

Sheet DCF Valuation
B1: DCF VALUATION — TESCO PLC (£ millions)
B2: Unlevered Free Cash Flow model | 3-year projection | Gordon Growth terminal value
B4: STEP 1 — WACC CALCULATION
B5: Risk-Free Rate (Rf) | C5: =Assumptions!C19 -> 0.042
B6: Equity Risk Premium (ERP) | C6: =Assumptions!C20 -> 0.06
B7: Beta (β) | C7: =Assumptions!C21 -> 0.65
B8: Cost of Equity — Ke = Rf + β × ERP | C8: =C5+C6*C7 -> 0.081
B9: Cost of Debt — Kd (pre-tax) | C9: =Assumptions!C22 -> 0.045
B10: Tax Rate | C10: =Assumptions!C16 -> 0.25
B11: Cost of Debt — Kd (post-tax) | C11: =C9*(1-C10) -> 0.03375
B12: Debt Weight (D/V) | C12: =Assumptions!C23 -> 0.35
B13: Equity Weight (E/V) | C13: =1-C12 -> 0.65
B14: WACC = Ke × (E/V) + Kd(1-T) × (D/V) | C14: =C8*C13+C11*C12 -> 0.0644625
B17: STEP 2 — UNLEVERED FREE CASH FLOW (UFCF)
B18: Line Item | C18: FY2026E | D18: FY2027E | E18: FY2028E
B19: EBIT | C19: ='Income Statement'!G19 -> 4026.7684 | D19: ='Income Statement'!H19 -> 4211.7317 | E19: ='Income Statement'!I19 -> 4391.9556
B20: Less: Tax on EBIT (NOPAT) | C20: =-ROUND(C19*Assumptions!C15,0) -> -77 | D20: =-ROUND(D19*Assumptions!D15,0) -> -80 | E20: =-ROUND(E19*Assumptions!E15,0) -> -83
B21: NOPAT (Net Op. Profit After Tax) | C21: =C19+C20 -> 3949.7684 | D21: =D19+D20 -> 4131.7317 | E21: =E19+E20 -> 4308.9556
B22: Add: D&A | C22: ='Income Statement'!G18 -> 78 | D22: ='Income Statement'!H18 -> 82 | E22: ='Income Statement'!I18 -> 85
B23: Less: Capex | C23: =-ROUND('Income Statement'!G6*Assumptions!C32,0) -> -1440 | D23: =-ROUND('Income Statement'!H6*Assumptions!D32,0) -> -1481 | E23: =-ROUND('Income Statement'!I6*Assumptions!E32,0) -> -1442
B24: Change in Working Capital | C24: =ROUND('Income Statement'!G6*Assumptions!C33,0) -> -216 | D24: =ROUND('Income Statement'!H6*Assumptions!D33,0) -> -222 | E24: =ROUND('Income Statement'!I6*Assumptions!E33,0) -> -152
B25: Unlevered Free Cash Flow (UFCF) | C25: =C21+C22+C23+C24 -> 2371.7684 | D25: =D21+D22+D23+D24 -> 2510.7317 | E25: =E21+E22+E23+E24 -> 2799.9556
B28: STEP 3 — DISCOUNTING CASH FLOWS
B29: Line Item | C29: FY2026E | D29: FY2027E | E29: FY2028E
B30: Period (year) | C30: 1 | D30: 2 | E30: 3
B31: Discount Factor [1/(1+WACC)^n] | C31: =1/(1+$C$14)^C30 -> 0.93944127 | D31: =1/(1+$C$14)^D30 -> 0.88254989 | E31: =1/(1+$C$14)^E30 -> 0.82910379
B32: PV of UFCF | C32: =C25*C31 -> 2228.1371 | D32: =D25*D31 -> 2215.846 | E32: =E25*E31 -> 2321.4538
B33: Sum of PV (FCFs) | C33: =SUM(C32:E32) -> 6765.4369
B35: STEP 4 — TERMINAL VALUE (GORDON GROWTH MODEL)
B36: Terminal Year UFCF (FY2028E) | C36: =E25 -> 2799.9556
B37: Terminal Growth Rate (g) | C37: =Assumptions!C25 -> 0.02
B38: WACC | C38: =C14 -> 0.0644625
B39: Terminal Value = UFCF × (1+g) / (WACC – g) | C39: =C36*(1+C37)/(C38-C37) -> 64232.887
B40: PV of Terminal Value | C40: =C39/(1+C14)^3 -> 53255.73
B41: % of EV from Terminal Value | C41: =C40/C46 -> 0.88728248 | D41: ← Key sanity check: if >80%, model is very sensitive to terminal assumptions
B42: % of EV from FCF (projection period) | C42: =C44/C46 -> 0.11271752
B43: STEP 5 — ENTERPRISE VALUE & EQUITY BRIDGE
B44: PV of Free Cash Flows (projection period) | C44: =C33 -> 6765.4369
B45: PV of Terminal Value | C45: =C40 -> 53255.73
B46: Enterprise Value (EV) | C46: =C44+C45 -> 60021.167
...

Sheet Trading Comps
B1: TRADING COMPARABLES — EUROPEAN FOOD RETAIL & WHOLESALE (£ millions)
B2: Source: Tesco PLC Annual Reports, Tesco Investor Relations, Stockanalysis.com, March 2026 | Share prices as of 28 Feb 2026 | NTM = Next Twelve Months consensus estimates
B4: PEER GROUP TRADING MULTIPLES
B5: Company | C5: Ticker | D5: Market Cap (£m) | E5: EV (£m) | F5: EV/EBITDA LTM | G5: EV/EBITDA NTM | H5: EV/EBIT NTM | I5: P/E NTM | J5: Revenue Growth NTM
B6: Tesco PLC ★ | C6: LSE: TSCO | D6: 21800 | E6: 37200 | F6: 9.6 | G6: 8.9 | H6: 14.1 | I6: 18.2 | J6: 0.025
B7: J Sainsbury | C7: LSE: SBRY | D7: 5600 | E7: 12800 | F7: 7.8 | G7: 7.2 | H7: 11.4 | I7: 14.8 | J7: 0.018
B8: Marks & Spencer | C8: LSE: MKS | D8: 7200 | E8: 9100 | F8: 10.2 | G8: 9.4 | H8: 15.8 | I8: 20.1 | J8: 0.04
B9: Ocado Group | C9: LSE: OCDO | D9: 3100 | E9: 4200 | F9: 28.4 | G9: 22.1 | H9: 40.2 | I9: N/M | J9: 0.12
B10: Carrefour SA | C10: EPA: CA | D10: 8400 | E10: 18600 | F10: 5.9 | G10: 5.5 | H10: 9.8 | I10: 12.4 | J10: 0.015
B11: Koninklijke Ahold | C11: AMS: AD | D11: 22100 | E11: 30400 | F11: 7.2 | G11: 6.8 | H11: 11.2 | I11: 14 | J11: 0.02
B12: Metro AG | C12: ETR: B4B | D12: 1100 | E12: 4200 | F12: 6.1 | G12: 5.8 | H12: 10.4 | I12: 13.2 | J12: 0.012
B14: Minimum (ex-Tesco) | F14: =MIN(F7:F12) -> 5.9 | G14: =MIN(G7:G12) -> 5.5 | H14: =MIN(H7:H12) -> 9.8 | I14: =MIN(I7:I11) -> 12.4 | J14: =MIN(J7:J12) -> 0.012
B15: Maximum (ex-Tesco) | F15: =MAX(F7:F12) -> 28.4 | G15: =MAX(G7:G12) -> 22.1 | H15: =MAX(H7:H12) -> 40.2 | I15: =MAX(I7:I11) -> 20.1 | J15: =MAX(J7:J12) -> 0.12
B16: Median (ex-Tesco) | F16: =MEDIAN(F7:F12) -> 7.5 | G16: =MEDIAN(G7:G12) -> 7 | H16: =MEDIAN(H7:H12) -> 11.3 | I16: =MEDIAN(I7:I11) -> 14.4 | J16: =MEDIAN(J7:J12) -> 0.019
B17: Mean (ex-Tesco) | F17: =AVERAGE(F7:F12) -> 10.933333 | G17: =AVERAGE(G7:G12) -> 9.4666667 | H17: =AVERAGE(H7:H12) -> 16.466667 | I17: =AVERAGE(I7:I11) -> 15.325 | J17: =AVERAGE(J7:J12) -> 0.0375
B20: IMPLIED VALUATION FROM COMPS MULTIPLES
B21: Tesco NTM EBITDA (£m) | C21: Source: Income Statement projection (FY2026E)
B22: Tesco NTM EBITDA (£m) | C22: ='Income Statement'!G14 -> 4104.7684
B23: Tesco NTM EBIT (£m) | C23: ='Income Statement'!G19 -> 4026.7684
B24: Tesco NTM EPS (£) | C24: ='Income Statement'!G23/7420 -> 0.44673428
B26: Implied EV — Median EV/EBITDA × EBITDA | C26: =G16*C22 -> 28733.379
B27: Implied EV — Mean EV/EBITDA × EBITDA | C27: =G17*C22 -> 38858.474
B29: Implied Share Price — Median Multiple (£) | C29: =(C26-'DCF Valuation'!C47-'DCF Valuation'!C48+'DCF Valuation'!C49)/'DCF Valuation'!C51 -> 5.4457383
B30: Implied Share Price — Mean Multiple (£) | C30: =(C27-'DCF Valuation'!C47-'DCF Valuation'!C48+'DCF Valuation'!C49)/'DCF Valuation'!C51 -> 6.8103064

Sheet Football Field
B1: VALUATION SUMMARY — FOOTBALL FIELD (Tesco PLC)
B2: All implied share prices in GBP (£) | Current share price: £3.42 (28 Feb 2026, Google Finance / Stockanalysis.com)
B4: VALUATION RANGE SUMMARY
B5: Methodology | C5: Low (£) | D5: Base (£) | E5: High (£)
B6: DCF — Bear Case (WACC 7.5%, TGR 1.5%) | C6: 3.04 | D6: — | E6: —
B7: DCF — Base Case (WACC 6.5%, TGR 2.0%) | C7: — | D7: ='DCF Valuation'!C52 -> 7.0818285 | E7: —
B8: DCF — Bull Case (WACC 5.5%, TGR 2.5%) | C8: — | D8: — | E8: 7.63
B9: Trading Comps — Median EV/EBITDA | C9: 2.6 | D9: ='Trading Comps'!C29 -> 5.4457383 | E9: 3.9
B10: Trading Comps — Mean EV/EBITDA | C10: 2.5 | D10: ='Trading Comps'!C30 -> 6.8103064 | E10: 4.1
B11: 52-Week Market Range | C11: 2.82 | D11: 3.42 | E11: 3.98
B14: ANALYST CONCLUSION
B15: Based on a blended DCF and Trading Comps analysis, Tesco PLC's implied share price range of £2.80–£4.10 suggests the stock is trading broadly in line with intrinsic value at the current market price of £3.42. The DCF base case (WACC 6.5%, TGR 2.0%) yields an implied price of approximately £3.60–£ 3.80, reflecting EBITDA margin expansion driven by Booker's wholesale growth and ongoing cost efficiency. IFRS 16 note: Net Debt of ~£11.4bn includes lease liabilities (~£8–9bn). On a pre-IFRS 16 basis, financial leverage would be materially lower, a critical distinction for credit analysis. Terminal Value represents ~70–75% of total EV, making the TGR and WACC assumptions the key model drivers. Key downside risks: consumer spending pressure, discounter competition (Aldi, Lidl), and lease obligations.
B20: KEY CREDIT METRICS (FY2024A)
B21: Net Debt / EBITDA | C21: 2.0x
B22: Interest Coverage (EBIT / Interest Expense) | C22: 4.2x
B23: FCF Yield | C23: ~2.5%
B24: Credit Rating (Moody's / S&P) | C24: Baa3 / BBB– (Investment Grade)
B25: Terminal Value as % of EV | C25: ='DCF Valuation'!C41 -> 0.88728248
